Workbook

Sheet 설정
A1: 항목 | B1: 값 | C1: 출처 / 비고
A2: 환율 EUR→KRW | B2: 1634 | C2: 2026-09-13 기준. 이 칸만 고치면 전 시트 환산이 갱신된다
A3: 작성일 | B3: 2026-09-13
A4: 업스트림 시트 | B4: docs.google.com/spreadsheets/d/1gq4iWWHEJVgAA_eemkTEsshXqrYlFxXAPwO515KpCJc | C4: 2026-09-13 스냅샷. 시트는 살아 있어 바뀔 수 있음
A5: 판단 근거 문서 | B5: BOM.md | C5: 절 번호는 '근거' 열 참조
A6: 전류 실측 | B6: ubai/current_probe.py | C6: 보행 평균 13.5A / 정지 8.1A — BMS·스위치·커넥터 정격의 근거

Sheet 발주
A1: Open Duck Mini v2 — 발주 워크시트 (한국 기준 환산)
A2: 업스트림 BOM 시트(2026-09-13 스냅샷)를 한국 조달 기준으로 옮긴 것. 단가는 업스트림 € 표기 그대로이고, 환산(₩)은 설정!B2 환율을 쓴 참고값이다 — 알리는 보통 이보다 싸다. 노란 칸(실구매가)에 실제 결제액을 채워 넣는다.
A4: 구분 | B4: 품목 | C4: 수량 | D4: 검색어 · 반드시 확인할 사양 | E4: 판정 | F4: 업스트림 단가(€) | G4: 업스트림 합계(€) | H4: 환산(₩) | I4: 실구매가(₩) | J4: 근거
A5: Wave1 알리 | B5: Feetech STS3215 서보 | C5: 14 | D5: STS3215 7.4V 19kg — ⚠️ 7.4V·19kg·cm 둘 다 표기된 것. ST3215(12V) 아님 | E5: 그대로 | F5: 14 | G5: =C5*F5 -> 196 | H5: =G5*설정!$B$2 -> 320264 | J5: §1
A6: Wave1 알리 | B6: Feetech FE-URT-1 서보 어댑터 | C6: 1 | D6: FE-URT-1 — 서보와 같은 스토어 묶음 가능. CH340 칩 | E6: 변경 | F6: 5 | G6: =C6*F6 -> 5 | H6: =G6*설정!$B$2 -> 8170 | J6: §2.2
A7: Wave1 알리 | B7: BNO055 9-DOF IMU | C7: 1 | D7: BNO055 9DOF — 저가품은 MPU 계열 클론 주의 | E7: 그대로 | F7: 40 | G7: =C7*F7 -> 40 | H7: =G7*설정!$B$2 -> 65360 | J7: §10
A8: Wave1 알리 | B8: 마이크로 스위치 SS-10 | C8: 4 | D8: SS-10GL micro switch (10개입) — 발 접지 감지 | E8: 그대로 | F8: 1 | G8: =C8*F8 -> 4 | H8: =G8*설정!$B$2 -> 6536
A9: Wave1 알리 | B9: SG90 9g 서보 | C9: 2 | D9: SG90 9g servo — 안테나(귀) 구동 | E9: 그대로 | F9: 3.33 | G9: =C9*F9 -> 6.66 | H9: =G9*설정!$B$2 -> 10882.44
A10: Wave1 알리 | B10: 626ZZ 베어링 | C10: 3 | D10: 626ZZ bearing 6x19x6 — ⚠️ 608ZZ 아님. 10개입 권장 | E10: 변경 | F10: 3.5 | G10: =C10*F10 -> 10.5 | H10: =G10*설정!$B$2 -> 17157 | J10: §1
A11: Wave1 알리 | B11: M3 열삽입 인서트 | C11: 1 | D11: M3 brass heat set insert — M3×5×4 계열, 100개입 | E11: 그대로 | F11: 5.99 | G11: =C11*F11 -> 5.99 | H11: =G11*설정!$B$2 -> 9787.66
A12: Wave1 알리 | B12: M3 나사 세트 | C12: 1 | D12: M3 hex socket screw kit — 6/8/10/12/16mm 혼합 | E12: 추가 | F12: 10 | G12: =C12*F12 -> 10 | H12: =G12*설정!$B$2 -> 16340 | J12: §3
A13: Wave1 알리 | B13: 2S BMS | C13: 1 | D13: 2S BMS 18650 8.4V 20A — ⚠️ 정격 20A 이상 (10A 짜리 5개입 주의) | E13: 변경 | F13: 8.4 | G13: =C13*F13 -> 8.4 | H13: =G13*설정!$B$2 -> 13725.6 | J13: §2.3
A14: Wave1 알리 | B14: 5V UBEC (레귤레이터) | C14: 1 | D14: 5V 3A UBEC — Pi+SG90+로직 전용. ⛔ 서보 전원으로 쓰지 말 것 | E14: 그대로 | F14: 4 | G14: =C14*F14 -> 4 | H14: =G14*설정!$B$2 -> 6536 | J14: §2.5
A15: Wave1 알리 | B15: 18650 2구 홀더 | C15: 1 | D15: 18650 2 slot holder — ⚠️ 양단 스프링, 풋프린트 ≤50×85mm | E15: 변경 | F15: 4.99 | G15: =C15*F15 -> 4.99 | H15: =G15*설정!$B$2 -> 8153.66 | J15: §2.1
A16: Wave1 알리 | B16: XT30 커넥터 (10쌍 세트) | C16: 1 | D16: XT30 connector pair — 암1+수2 사용(배터리·파워서플라이). 배럴잭 대체 | E16: 변경 | F16: 8 | G16: =C16*F16 -> 8 | H16: =G16*설정!$B$2 -> 13072 | J16: §2.5
A17: Wave1 알리 | B17: 소형 전원 스위치 | C17: 1 | D17: mini rocker switch — ⚠️ 정격 15A 이상 | E17: 변경 | F17: 4.49 | G17: =C17*F17 -> 4.49 | H17: =G17*설정!$B$2 -> 7336.66 | J17: §2.4
A18: Wave1 알리 | B18: micro-USB↔USB-C 케이블 15cm | C18: 1 | E18: 그대로 | F18: 7 | G18: =C18*F18 -> 7 | H18: =G18*설정!$B$2 -> 11438
A19: Wave1 알리 | B19: micro-USB↔USB-C 케이블 50cm | C19: 1 | E19: 그대로 | F19: 6 | G19: =C19*F19 -> 6 | H19: =G19*설정!$B$2 -> 9804
A20: Wave1 알리 | B20: 케이블 슬리브(사복관) | C20: 1 | D20: cable sleeve braided | E20: 그대로 | F20: 9 | G20: =C20*F20 -> 9 | H20: =G20*설정!$B$2 -> 14706
A21: Wave1 알리 | B21: 피아노선 Ø1.5~2mm×150mm + 비즈 | C21: 2 | D21: 안테나 대체품 — antenna.stl 은 FDM 출력 불가 | E21: 추가 | F21: 1 | G21: =C21*F21 -> 2 | H21: =G21*설정!$B$2 -> 3268 | J21: §3
A22: Wave1 알리 | B22: Raspberry Pi Zero 2W | C22: 1 | D22: ⚠️ 가품·핀헤더 확인. 품절/의심이면 국내로 | E22: 그대로 | F22: 26.08 | G22: =C22*F22 -> 26.08 | H22: =G22*설정!$B$2 -> 42614.72 | J22: §2
A23: Wave2 국내 | B23: 18650 셀 (삼성SDI 30Q) | C23: 2 | D23: 삼성SDI 30Q — ⚠️ 비보호 플랫탑 · 제목에 '삼성SDI' + '15A' + KC. ⛔ 항공제한으로 국내 강제, 같은 배치 2개 한 번에 | E23: 변경 | F23: 5 | G23: =C23*F23 -> 10 | H23: =G23*설정!$B$2 -> 16340 | J23: §2.1
A24: Wave2 국내 | B24: microSD 32GB+ | C24: 1 | D24: ⚠️ 알리 용량 위조 흔함 → 국내 정품. 설치 후 raspi-config 로 파일시스템 확장 | E24: 변경 | F24: 10 | G24: =C24*F24 -> 10 | H24: =G24*설정!$B$2 -> 16340 | J24: §4
A25: Wave2 국내 | B25: 18650 충전기 (2구 이상) | C25: 1 | D25: 슬롯별 독립 · 리튬이온 4.2V · 0.5~1A. 업스트림 USB-C 모듈 대체 | E25: 대체 | F25: 9.99 | G25: =C25*F25 -> 9.99 | H25: =G25*설정!$B$2 -> 16323.66 | J25: §4.1
A26: 출력 외주 | B26: JLC3DP SLS 3201PA-F (15종 26개) | C26: 1 | D26: 257cm³ × $0.18/g ≈ $46. 얇은 판재 — FDM 최소크기 미달분 | E26: 변경 | F26: 28 | G26: =C26*F26 -> 28 | H26: =G26*설정!$B$2 -> 45752 | J26: §5
A27: 출력 외주 | B27: JLC3DP FDM PLA (20종) | C27: 1 | D27: head/body_*/trunk_*/foot_top/foot_side 등. ⚠️ Instant Quote 필요 | E27: 변경 | F27: 0 | G27: =C27*F27 -> 0 | H27: =G27*설정!$B$2 -> 0 | J27: §5
A28: 출력 외주 | B28: JLC3DP FDM TPU (foot_bottom_tpu ×2) | C28: 1 | D28: ⚠️ Z 8mm 로 최소치 미달 — 형상 보정 필요 | E28: 변경 | F28: 0 | G28: =C28*F28 -> 0 | H28: =G28*설정!$B$2 -> 0 | J28: §5
A29: 선택 | B29: Xbox One 컨트롤러 | C29: 1 | D29: 런타임 기본 조종 입력. 명령 7채널이 0이면 제자리에 서 있음 | E29: 추가 | F29: 0 | G29: =C29*F29 -> 0 | H29: =G29*설정!$B$2 -> 0 | J29: §7
A30: 선택 | B30: 표정 패키지 (스피커·앰프·LED·디퓨저·리플렉터) | C30: 1 | D30: ⚠️ 시트 단가는 분할단가. 실구매 = 스피커6+리플렉터2+LED10+디퓨저10+앰프10 | E30: 변경 | F30: 38 | G30: =C30*F30 -> 38 | H30: =G30*설정!$B$2 -> 62092 | J30: §7
A31: 선택 | B31: XIAO ESP32S3 Sense | C31: 1 | D31: 비전용(~$14). Wave1 에 끼워도 배송 안 바뀜 → 일정 위험 0 | E31: 추가 | F31: 12 | G31: =C31*F31 -> 12 | H31: =G31*설정!$B$2 -> 19608 | J31: §7
A32: 선택 | B32: 여분 18650 셀 2개 | C32: 2 | D32: 벤치 전원 대신 팩 2벌 운용 — 파워서플라이(10만원대)보다 훨씬 쌈 | E32: 추가 | F32: 5 | G32: =C32*F32 -> 10 | H32: =G32*설정!$B$2 -> 16340 | J32: §2.5
... A39: 제외 | B39: TPU 필라멘트 | C39: 1 | D39: ⛔ 동일 | E39: 삭제 | F39: 0 | G39: =C39*F39 -> 0 | H39: =G39*설정!$B$2 -> 0 | J39: §5
B41: 구분별 합계
B42: Wave 1 — 알리익스프레스 (오늘 발주, 2~4주) | G42: =SUMIF($A$5:$A$39,"Wave1 알리",$G$5:$G$39) -> 358.11 | H42: =G42*설정!$B$2 -> 585151.74 | I42: =SUMIF($A$5:$A$39,"Wave1 알리",$I$5:$I$39) -> 0
B43: Wave 2 — 국내 (이번 주, 1~3일) | G43: =SUMIF($A$5:$A$39,"Wave2 국내",$G$5:$G$39) -> 29.99 | H43: =G43*설정!$B$2 -> 49003.66 | I43: =SUMIF($A$5:$A$39,"Wave2 국내",$I$5:$I$39) -> 0
B44: Wave 3 — JLC3DP 출력 외주 | G44: =SUMIF($A$5:$A$39,"출력 외주",$G$5:$G$39) -> 28 | H44: =G44*설정!$B$2 -> 45752 | I44: =SUMIF($A$5:$A$39,"출력 외주",$I$5:$I$39) -> 0
B45: 선택 — 나중에 사도 되는 것 | G45: =SUMIF($A$5:$A$39,"선택",$G$5:$G$39) -> 60 | H45: =G45*설정!$B$2 -> 98040 | I45: =SUMIF($A$5:$A$39,"선택",$I$5:$I$39) -> 0
B46: ⛔ 제외 — 사지 않는 것 (아낀 금액) | G46: =SUMIF($A$5:$A$39,"제외",$G$5:$G$39) -> 56.99 | H46: =G46*설정!$B$2 -> 93121.66 | I46: =SUMIF($A$5:$A$39,"제외",$I$5:$I$39) -> 0
B48: ■ 지금 발주 합계 (Wave 1+2+3, 선택·제외 빼고) | G48: =SUM(G42:G44) -> 416.1 | H48: =G48*설정!$B$2 -> 679907.4 | I48: =SUM(I42:I44) -> 0
B50: 환산(₩) 은 업스트림 € × 설정!B2 환율이다. 실제 알리 가격은 보통 이보다 싸므로 상한으로 본다.
...

Sheet bom링크
D1: 개수 | E1: 개당 가격 | F1: 총가격 | G1: 비고
A2: 전원 | B2: 18650 셀 (Molicel INR18650-P30B) | D2: 2 | F2: =D2*E2 -> 0 | G2: 왜 해외 안됨? 클로드 피셜
B3: 18650 홀더 | D3: 1 | F3: =D3*E3 -> 0 | G3: 왜 해외 안됨? 클로드 피셜아무튼 미룸
B4: 2S BMS | D4: 1 | E4: 3240 | F4: =D4*E4 -> 3240 | G4: 3개 여분 | H4: https://ko.aliexpress.com/item/1005012432601159.html?spm=a2g0o.cart.0.0.43485ea2IKZauB&mp=1&pdp_npi=6%40dis%21KRW%21KRW%203448%21KRW%203240%21%21KRW%203240%21%21%21%40212a6df517893153370553915e0fda%2112000058362683244%21ct%21KR%218166665694%21%211%210%21&gatewayAdapt=glo2kor
B5: 5V 레귤레이터 | D5: 1 | E5: 11575 | F5: =D5*E5 -> 11575 | H5: https://ko.aliexpress.com/item/1005009420262174.html?spm=a2g0o.cart.0.0.31185ea2yYj8Kt&mp=1&pdp_npi=6%40dis%21KRW%21KRW+26768%21KRW+11575%21%21KRW+11575%21%21%21%40212a6df517893153126563246e0fda%2112000049436758291%21ct%21KR%218166665694%21%211%210%21&gatewayAdapt=glo2kor
B6: 소형 전원 스위치 | D6: 1 | E6: 3400 | F6: =D6*E6 -> 3400 | H6: https://ko.aliexpress.com/item/1005008045270070.html?spm=a2g0o.productlist.main.5.3bb6w3scw3sc14&algo_pvid=954f1409-078c-43e8-9525-3b33cf9e4726&algo_exp_id=954f1409-078c-43e8-9525-3b33cf9e4726-4&pdp_ext_f=%7B%22order%22%3A%22248%22%2C%22eval%22%3A%221%22%2C%22fromPage%22%3A%22search%22%7D&pdp_npi=6%40dis%21KRW%213907%211500%21%21%2118.90%217.25%21%402140ec2d17893144675913650e0e25%2112000043407119266%21sea%21KR%218166665694%21ABX%211%210%21n_tag%3A-29910%3Bd%3A6e0fef8a%3Bm03_new_user%3A-29895%3BpisId%3A5000000217075891&curPageLogUid=U8DliTo0Afgh&utparam-url=scene%3Asearch%7Cquery_from%3A%7Cx_object_id%3A1005008045270070%7C_p_origin_prod%3A
B7: USB-C 충전기 | D7: 1 | F7: =D7*E7 -> 0 | G7: 있음
B8: 2.1mm 배럴잭 | D8: 2 | F8: 1750 | G8: 1개 사서 반 자르면 됨 | H8: https://www.aliexpress.com/ssr/300000512/kr2024update?spm=a2g0o.productlist.main.1.638czRe6zRe6w4&productIds=1005009225198466%3A12000048380333444&pha_manifest=ssr&_immersiveMode=true&disableNav=YES&sourceName=SEARCHProduct&utparam-url=scene%3Asearch%7Cquery_from%3A%7Cx_object_id%3A1005009225198466%7C_p_origin_prod%3A&pvid=f7c9a41b-050f-49e3-853f-9857a1fb0291&_gl=1*1si3d74*_gcl_aw*R0NMLjE3ODkxMzMxODQuQ2owS0NRand6WTdWQmhEd0FSSXNBRnRQdkJUUFBralFPY3JlODBXb3pNMms4UkRRQzY2b0JadGZRajk4NndVMUVrbVB4cnBoMDkyN3E0c2FBbmJlRUFMd193Y0I.*_gcl_dc*R0NMLjE3ODkxMzMxODQuQ2owS0NRand6WTdWQmhEd0FSSXNBRnRQdkJUUFBralFPY3JlODBXb3pNMms4UkRRQzY2b0JadGZRajk4NndVMUVrbVB4cnBoMDkyN3E0c2FBbmJlRUFMd193Y0I.*_gcl_au*MTczMTUyODg0OS4xNzg5MDQ1MDI5*_ga*MTcwNzgwNjEuMTc4OTA0NTAyOQ..*_ga_VED1YSGNC7*czE3ODkzNDc4OTgkbzckZzEkdDE3ODkzNDc5MTIkajQ2JGwwJGgw
B9: XT30 | D9: 1 | E9: 1500 | F9: =D9*E9 -> 1500 | H9: https://ko.aliexpress.com/item/1005012351469865.html?spm=a2g0o.cart.0.0.77c45ea2LAVLuG&mp=1&pdp_npi=6%40dis%21KRW%21KRW+8089%21KRW+3640%21%21KRW+3640%21%21%21%400be71e1e17893136155816780e0c7b%2112000058147347073%21ct%21KR%218166665694%21%211%210%21&gatewayAdapt=glo2kor
A10: 서보·제어·센서 | B10: Feetech STS3215 (7.4V) | D10: 14 | E10: 19094 | F10: =16*(E10) -> 305504 | G10: 알리바바2개 추가 구매 | H10: https://www.alibaba.com/product-detail/Low-Cost-Feetech-STS3215-Servo-7_1601611431055.html?spm=a2700.prosearch.normal_offer.d_image.353667afKTd0Xq&selectedCarrierCode=SEMI_MANAGED_ECONOMIC%40%40ECONOMY&priceId=67301407777347eca97c467d2b885f68
B11: IMU BNO055 | D11: 1 | E11: 8452 | F11: =D11*E11 -> 8452 | G11: 배송비 따로 | H11: https://ko.aliexpress.com/item/1005012422810015.html?spm=a2g0o.productlist.main.2.9bdfNESbNESb3k&algo_pvid=193551a3-c3db-4df1-ae53-932f6e2682e4&algo_exp_id=193551a3-c3db-4df1-ae53-932f6e2682e4-1&pdp_ext_f=%7B%22order%22%3A%2247%22%2C%22eval%22%3A%221%22%2C%22fromPage%22%3A%22search%22%7D&pdp_npi=6%40dis%21KRW%2112230%218452%21%21%2159.16%2140.89%21%40214131cd17893118527064026e0db1%2112000058318563317%21sea%21KR%218166665694%21ABX%211%210%21n_tag%3A-29910%3Bd%3A6e0fef8a%3Bm03_new_user%3A-29895%3BpisId%3A5000000217075891&curPageLogUid=qd6xt0pARPXm&utparam-url=scene%3Asearch%7Cquery_from%3A%7Cx_object_id%3A1005012422810015%7C_p_origin_prod%3A
B12: Raspberry Pi Zero 2W | D12: 1 | E12: 58500 | F12: =D12*E12 -> 58500 | G12: 구하기 힘듦 | H12: https://www.coupang.com/vp/products/9676374699?vendorItemId=95864602021&sourceType=CART
B13: SD 카드 | C13: 완 | D13: 1 | E13: 2500 | F13: =D13*E13 -> 2500 | G13: 쿠팡와우 배송비 | H13: https://www.coupang.com/vp/products/29584980?itemId=113174421&vendorItemId=70805744236&src=1032034&spec=10305199&addtag=400&ctag=29584980&lptag=V70805744236&itime=20260914000034&pageType=PRODUCT&pageValue=29584980&wPcid=17893105135136394208605&wRef=prod.danawa.com&wTime=20260914000034&redirect=landing&mcid=b2ef12544a31492faa7e56527c42c343
B14: 서보 컨트롤 보드 | D14: 1 | E14: 8500 | F14: =D14*E14 -> 8500 | H14: https://ko.aliexpress.com/item/1005008842742388.html?spm=a2g0o.productlist.main.1.49d8p05bp05bPf&algo_pvid=e9d7f3f8-cd26-4a6f-8976-503291bc9f92&algo_exp_id=e9d7f3f8-cd26-4a6f-8976-503291bc9f92-0&pdp_ext_f=%7B%22order%22%3A%22264%22%2C%22eval%22%3A%221%22%2C%22fromPage%22%3A%22search%22%7D&pdp_npi=6%40dis%21KRW%218842%218500%21%21%2142.77%2141.11%21%402141147417893120301441213e0ec6%2112000057223247889%21sea%21KR%218166665694%21ABX%211%210%21n_tag%3A-29910%3Bd%3A6e0fef8a%3Bm03_new_user%3A-29895&curPageLogUid=QswbvQzV7RA7&utparam-url=scene%3Asearch%7Cquery_from%3A%7Cx_object_id%3A1005008842742388%7C_p_origin_prod%3A
B15: 발 접점 스위치 SS-10 | D15: 4 | E15: 3000 | F15: =E15 -> 3000 | G15: 2종류 스위치 | H15: https://ko.aliexpress.com/item/1005009049556408.html?spm=a2g0o.cart.0.0.6e405ea24xWlaj&mp=1&pdp_npi=6%40dis%21KRW%21KRW%203324%21KRW%201500%21%21KRW%201500%21%21%21%40210178d717893124779647521e0ed3%2112000047711627686%21ct%21KR%218166665694%21%211%210%21&gatewayAdapt=glo2kor
B16: 9g 서보 | D16: 2 | E16: 2748 | F16: =4*E16 -> 10992 | G16: 2개 예비 | H16: https://ko.aliexpress.com/item/1005012556957081.html?spm=a2g0o.cart.0.0.f0685ea2WtV3At&mp=1&pdp_npi=6%40dis%21KRW%21KRW+31364%21KRW+13800%21%21KRW+13800%21%21%21%402102ef5e17893131522141579e0e12%2112000058694173047%21ct%21KR%218166665694%21%211%210%21&gatewayAdapt=glo2kor
A17: 기타 | B17: M3 열삽입 인서트 | D17: 1 | E17: 1700 | F17: 1700 | H17: https://www.aliexpress.com/ssr/300000512/kr2024update?spm=a2g0o.productlist.main.1.c1cbAiv4Aiv4hE&productIds=1005007995311296%3A12000043196473113&pha_manifest=ssr&_immersiveMode=true&disableNav=YES&sourceName=SEARCHProduct&utparam-url=scene%3Asearch%7Cquery_from%3A%7Cx_object_id%3A1005007995311296%7C_p_origin_prod%3A&pvid=20265dd5-c941-4ad4-93f1-c6ad99c7ea0b&_gl=1*1lcyaza*_gcl_aw*R0NMLjE3ODkxMzMxODQuQ2owS0NRand6WTdWQmhEd0FSSXNBRnRQdkJUUFBralFPY3JlODBXb3pNMms4UkRRQzY2b0JadGZRajk4NndVMUVrbVB4cnBoMDkyN3E0c2FBbmJlRUFMd193Y0I.*_gcl_dc*R0NMLjE3ODkxMzMxODQuQ2owS0NRand6WTdWQmhEd0FSSXNBRnRQdkJUUFBralFPY3JlODBXb3pNMms4UkRRQzY2b0JadGZRajk4NndVMUVrbVB4cnBoMDkyN3E0c2FBbmJlRUFMd193Y0I.*_gcl_au*MTczMTUyODg0OS4xNzg5MDQ1MDI5*_ga*MTcwNzgwNjEuMTc4OTA0NTAyOQ..*_ga_VED1YSGNC7*czE3ODkzNDMyMDckbzYkZzEkdDE3ODkzNDMyMTIkajU1JGwwJGgw
B18: PLA 필라멘트 | D18: 1 | E18: 18000 | F18: =D18*E18 -> 18000 | H18: https://kr.store.bambulab.com/products/pla-basic-filament?id=565422076437794836
B19: TPU 필라멘트 | D19: 1 | E19: 33600 | F19: =D19*E19 -> 33600 | G19: 2개 3d 맡기기 | H19: https://app.eyecontact.kr/my-page?section=orders
B20: 케이블 슬리브 | D20: 1 | E20: 1500 | F20: =D20*E20 -> 1500 | G20: 4 | H20: https://ko.aliexpress.com/item/1005010448843241.html?spm=a2g0o.productlist.main.5.5a936dd1CB709t&algo_pvid=072503f4-2588-4ee5-a8de-0f1dc37106f5&algo_exp_id=072503f4-2588-4ee5-a8de-0f1dc37106f5-4&pdp_ext_f=%7B%22order%22%3A%22158%22%2C%22eval%22%3A%221%22%2C%22fromPage%22%3A%22search%22%7D&pdp_npi=6%40dis%21KRW%216110%211500%21%21%2129.60%217.27%21%402102eb1417893625896023956e0d2c%2112000052446292744%21sea%21KR%218166665694%21ABX%211%210%21n_tag%3A-29910%3Bd%3A6e0fef8a%3Bm03_new_user%3A-29895%3BpisId%3A5000000217075891&curPageLogUid=b68vUd83AUed&utparam-url=scene%3Asearch%7Cquery_from%3A%7Cx_object_id%3A1005010448843241%7C_p_origin_prod%3A
B21: micro-USB↔USB-C 15cm | D21: 1 | F21: =D21*E21 -> 0
B22: micro-USB↔USB-C 50cm | D22: 1 | F22: =D22*E22 -> 0
B23: 베어링 | D23: 3 | E23: 6170 | F23: 6170 | G23: 5개짜리 | H23: https://ko.aliexpress.com/item/1005004328211697.html?spm=a2g0o.productlist.main.4.7907SrdzSrdz01&algo_pvid=6d68a95a-dc7b-4738-b129-940ca0a47f6b&algo_exp_id=6d68a95a-dc7b-4738-b129-940ca0a47f6b-3&pdp_ext_f=%7B%22order%22%3A%2238%22%2C%22spu_best_type%22%3A%22price%22%2C%22eval%22%3A%221%22%2C%22fromPage%22%3A%22search%22%7D&pdp_npi=6%40dis%21KRW%216512%216140%21%21%2131.55%2129.75%21%400b14ce1917893621951035355e1347%2112000028772990035%21sea%21KR%218166665694%21ABX%211%210%21n_tag%3A-29910%3Bd%3A6e0fef8a%3Bm03_new_user%3A-29895&curPageLogUid=gHUf68BYGOBK&utparam-url=scene%3Asearch%7Cquery_from%3A%7Cx_object_id%3A1005004328211697%7C_p_origin_prod%3A
A24: 표정(선택) | B24: 프로젝터 리플렉터 | D24: 1 | F24: =D24*E24 -> 0
B25: 스피커 | D25: 1 | F25: =D25*E25 -> 0
B26: LED (눈·프로젝터) | D26: 3 | F26: =D26*E26 -> 0
B27: 마이크 | D27: 1 | F27: =D27*E27 -> 0
B28: 아이 디퓨저 | D28: 4 | F28: =D28*E28 -> 0
B29: 앰프 | D29: 1 | F29: =D29*E29 -> 0
B30: Raspberry Pi 카메라 | D30: 1 | F30: =D30*E30 -> 0
F31: =SUM(F2:F30) -> 479883

Sheet 업스트림원본
A1: 섹션 | B1: 부품 | C1: 수량 | D1: 단가(€) | E1: 합계(€) | F1: 링크 | G1: 시트 주석
A2: 전원 | B2: 18650 셀 (Molicel INR18650-P30B) | C2: 2 | D2: 5 | E2: 10 | F2: nkon.nl | G2: 가장 빵빵한 걸로. 나는 3000mAh / 30A
A3: 전원 | B3: 18650 홀더 | C3: 1 | D3: 4.99 | E3: 4.99 | F3: amazon.fr
A4: 전원 | B4: 2S BMS | C4: 1 | D4: 8.4 | E4: 8.4 | F4: shorturl.at
A5: 전원 | B5: 5V 레귤레이터 | C5: 1 | D5: 4 | E5: 4 | F5: alibaba.com
A6: 전원 | B6: 소형 전원 스위치 | C6: 1 | D6: 4.49 | E6: 4.49 | F6: amazon.fr | G6: 하나만 필요
A7: 전원 | B7: USB-C 충전기 | C7: 1 | D7: 9.99 | E7: 9.99 | F7: amazon.fr | G7: 하나만 필요
A8: 전원 | B8: 2.1mm 배럴잭 | C8: 2 | D8: 1 | E8: 2 | F8: amazon.fr | G8: 두 개 필요
A9: 전원 | B9: XT30 | C9: 1 | D9: 8 | E9: 8 | F9: amazon.fr | G9: 한 쌍만 필요하지만 낱개 구매가 어려움
A10: 서보·제어·센서 | B10: Feetech STS3215 (7.4V) | C10: 14 | D10: 14 | E10: 196 | F10: alibaba.com | G10: 반드시 7.4V, 별칭 19kg.cm
A11: 서보·제어·센서 | B11: IMU BNO055 | C11: 1 | D11: 40 | E11: 40 | F11: amazon.fr | G11: 더 싼 대안 필요. 알리에 1달러짜리 봄
A12: 서보·제어·센서 | B12: Raspberry Pi Zero 2W | C12: 1 | D12: 26.08 | E12: 26.08 | F12: t.ly
A13: 서보·제어·센서 | B13: SD 카드 | C13: 1 | D13: 10 | E13: 10 | F13: amazon.fr | G13: 더 싸게 구할 수 있음
A14: 서보·제어·센서 | B14: 서보 컨트롤 보드 | C14: 1 | D14: 5 | E14: 5 | F14: waveshare.com
A15: 서보·제어·센서 | B15: 발 접점 스위치 SS-10 | C15: 4 | D15: 1 | E15: 4 | F15: aliexpress.fr
A16: 서보·제어·센서 | B16: 9g 서보 | C16: 2 | D16: 3.33 | E16: 6.66 | F16: amazon.fr
A17: 기타 | B17: M3 열삽입 인서트 | C17: 1 | D17: 5.99 | E17: 5.99 | F17: amazon.fr
A18: 기타 | B18: PLA 필라멘트 | C18: 1 | D18: 20 | E18: 20 | G18: 이미 있으면 무료
A19: 기타 | B19: TPU 필라멘트 | C19: 1 | D19: 0 | E19: 0 | G19: 발바닥용, 비용 무시 가능
A20: 기타 | B20: 케이블 슬리브 | C20: 1 | D20: 9 | E20: 9 | F20: amazon.fr
A21: 기타 | B21: micro-USB↔USB-C 15cm | C21: 1 | D21: 7 | E21: 7 | F21: amazon.fr
A22: 기타 | B22: micro-USB↔USB-C 50cm | C22: 1 | D22: 6 | E22: 6 | F22: amazon.fr
A23: 기타 | B23: 베어링 | C23: 3 | D23: 3.5 | E23: 10.5 | F23: amazon.fr
A24: 표정(선택) | B24: 프로젝터 리플렉터 | C24: 1 | D24: 2 | E24: 2 | F24: aliexpress.fr
A25: 표정(선택) | B25: 스피커 | C25: 1 | D25: 6 | E25: 6 | F25: amazon.fr
A26: 표정(선택) | B26: LED (눈·프로젝터) | C26: 3 | D26: 0.2 | E26: 0.6 | F26: amazon.fr | G26: 50개를 ~10€ 에 사야 함
A27: 표정(선택) | B27: 마이크 | C27: 1 | D27: 15 | E27: 15 | F27: amazon.fr | G27: 너무 비쌈 (아직 통합 안 됨)
A28: 표정(선택) | B28: 아이 디퓨저 | C28: 4 | D28: 0.16 | E28: 0.64 | F28: amazon.fr | G28: 60개를 ~10€ 에 사야 함
A29: 표정(선택) | B29: 앰프 | C29: 1 | D29: 5 | E29: 5 | F29: amazon.fr | G29: 2개를 ~10€ 에 사야 함
A30: 표정(선택) | B30: Raspberry Pi 카메라 | C30: 1 | D30: 5 | E30: 5 | F30: aliexpress.fr | G30: 아직 통합 안 됨
B31: 시트 표기 합계: 기본 398.1€ (최저가 331.1€) / 표정 포함 432.34€
B32: 검산: 전원 51.87 + 서보 287.74 + 기타 58.49 = 398.10 ✓ (시트의 전원·기타 소계 칸은 행 합과 어긋나지만 총계는 맞음 → 행 수치를 신뢰)
